[SYSTEM] Scheduler started - Log file: scheduler_log_20251110_122155.txt
[SYSTEM] Connected to server at 127.0.0.1:12345
[RECEIVER] Recieved Process Info: 1 9 
[RUNNING] Process 1 started with remaining burst time 9
[PREEMPTED] Process 1 preempted, 8 seconds remaining
[RUNNING] Process 1 started with remaining burst time 8
[PREEMPTED] Process 1 preempted, 7 seconds remaining
[RUNNING] Process 1 started with remaining burst time 7
[PREEMPTED] Process 1 preempted, 6 seconds remaining
[RUNNING] Process 1 started with remaining burst time 6
[RECEIVER] Recieved Process Info: 2 17 
[PREEMPTED] Process 1 preempted, 5 seconds remaining
[RUNNING] Process 2 started with remaining burst time 17
[PREEMPTED] Process 2 preempted, 16 seconds remaining
[RUNNING] Process 1 started with remaining burst time 5
[RECEIVER] Recieved Process Info: 3 7 
[PREEMPTED] Process 1 preempted, 4 seconds remaining
[RUNNING] Process 2 started with remaining burst time 16
[PREEMPTED] Process 2 preempted, 15 seconds remaining
[RUNNING] Process 3 started with remaining burst time 7
[PREEMPTED] Process 3 preempted, 6 seconds remaining
[RUNNING] Process 1 started with remaining burst time 4
[PREEMPTED] Process 1 preempted, 3 seconds remaining
[RUNNING] Process 2 started with remaining burst time 15
[RECEIVER] Recieved Process Info: 4 8 
[PREEMPTED] Process 2 preempted, 14 seconds remaining
[RUNNING] Process 3 started with remaining burst time 6
[PREEMPTED] Process 3 preempted, 5 seconds remaining
[RUNNING] Process 1 started with remaining burst time 3
[PREEMPTED] Process 1 preempted, 2 seconds remaining
[RUNNING] Process 4 started with remaining burst time 8
[PREEMPTED] Process 4 preempted, 7 seconds remaining
[RUNNING] Process 2 started with remaining burst time 14
[RECEIVER] Recieved Process Info: 5 1 
[PREEMPTED] Process 2 preempted, 13 seconds remaining
[RUNNING] Process 3 started with remaining burst time 5
[SHELL] Scheduler paused by user.
[PREEMPTED] Process 3 preempted, 4 seconds remaining
[RECEIVER] Recieved Process Info: 6 3 
[RECEIVER] Recieved Process Info: 7 1 
[RECEIVER] Recieved Process Info: 8 10 
[RECEIVER] Received END message
