[SYSTEM] Scheduler started - Log file: scheduler_log_20251110_175226.txt
[SYSTEM] Connected to server at 127.0.0.1:12345
[RECEIVER] Recieved Process Info: 1 9 
[RUNNING] Process 1 started with remaining burst time 9
[PREEMPTED] Process 1 preempted, 7 seconds remaining
[RUNNING] Process 1 started with remaining burst time 7
[PREEMPTED] Process 1 preempted, 5 seconds remaining
[RUNNING] Process 1 started with remaining burst time 5
[PREEMPTED] Process 1 preempted, 3 seconds remaining
[RUNNING] Process 1 started with remaining burst time 3
[RECEIVER] Recieved Process Info: 2 3 
[PREEMPTED] Process 1 preempted, 1 seconds remaining
[RUNNING] Process 2 started with remaining burst time 3
[PREEMPTED] Process 2 preempted, 1 seconds remaining
[RUNNING] Process 1 started with remaining burst time 1
[COMPLETED] Process 1 finished after total burst 1s
[RUNNING] Process 2 started with remaining burst time 1
[COMPLETED] Process 2 finished after total burst 1s
[RECEIVER] Recieved Process Info: 3 15 
[RUNNING] Process 3 started with remaining burst time 15
[PREEMPTED] Process 3 preempted, 13 seconds remaining
[RUNNING] Process 3 started with remaining burst time 13
[PREEMPTED] Process 3 preempted, 11 seconds remaining
[RUNNING] Process 3 started with remaining burst time 11
[PREEMPTED] Process 3 preempted, 9 seconds remaining
[RUNNING] Process 3 started with remaining burst time 9
[RECEIVER] Recieved Process Info: 4 1 
[PREEMPTED] Process 3 preempted, 7 seconds remaining
[RUNNING] Process 4 started with remaining burst time 1
[COMPLETED] Process 4 finished after total burst 1s
[RUNNING] Process 3 started with remaining burst time 7
[PREEMPTED] Process 3 preempted, 5 seconds remaining
[RUNNING] Process 3 started with remaining burst time 5
[RECEIVER] Recieved Process Info: 5 1 
[PREEMPTED] Process 3 preempted, 3 seconds remaining
[RUNNING] Process 5 started with remaining burst time 1
[COMPLETED] Process 5 finished after total burst 1s
[RUNNING] Process 3 started with remaining burst time 3
[PREEMPTED] Process 3 preempted, 1 seconds remaining
[RUNNING] Process 3 started with remaining burst time 1
[COMPLETED] Process 3 finished after total burst 1s
[RECEIVER] Recieved Process Info: 6 9 
[RUNNING] Process 6 started with remaining burst time 9
[PREEMPTED] Process 6 preempted, 7 seconds remaining
[RUNNING] Process 6 started with remaining burst time 7
[RECEIVER] Recieved Process Info: 7 6 
[PREEMPTED] Process 6 preempted, 5 seconds remaining
[RUNNING] Process 7 started with remaining burst time 6
[PREEMPTED] Process 7 preempted, 4 seconds remaining
[RUNNING] Process 6 started with remaining burst time 5
[RECEIVER] Recieved Process Info: 8 3 
[PREEMPTED] Process 6 preempted, 3 seconds remaining
[RUNNING] Process 7 started with remaining burst time 4
[PREEMPTED] Process 7 preempted, 2 seconds remaining
[RUNNING] Process 8 started with remaining burst time 3
[PREEMPTED] Process 8 preempted, 1 seconds remaining
[RUNNING] Process 6 started with remaining burst time 3
[PREEMPTED] Process 6 preempted, 1 seconds remaining
[RUNNING] Process 7 started with remaining burst time 2
[COMPLETED] Process 7 finished after total burst 2s
[RUNNING] Process 8 started with remaining burst time 1
[COMPLETED] Process 8 finished after total burst 1s
[RUNNING] Process 6 started with remaining burst time 1
[COMPLETED] Process 6 finished after total burst 1s
[RECEIVER] Received END message
[SCHEDULER] Received END signal, shutting down...
